Workbook

Sheet Как пользоваться
B1: М А Н У Ф А К Т У Р А 4 · К У Р С « Б Р Е Н Д П О Д К Л Ю Ч »
B2: СМЕТА ЗАПУСКА БРЕНДА ОДЕЖДЫ
B3: Анна Желтакова · соосновательница швейного производства «Мануфактура 4»
B6: З А Ч Е М Э Т А Т А Б Л И Ц А
B7: Первый вопрос, который мне задают: «Сколько нужно денег на бренд?». Таблица отвечает на него до того, как вы отдадите деньги фабрике.
B9: К А К З А П О Л Н И Т Ь
B10: 1. «Калькулятор»: себестоимость каждой модели по статьям — ткань и подкладка, фурнитура, раскрой, пошив, ВТО, ОТК, маркировка, упаковка. Внизу — розничная цена и сколько вы заработаете с вещи на сайте, маркетплейсе, в реализации и в опте.
B11: 2. «Капсула»: сколько размеров и штук на размер шьёте. Модели 1–5 подтягиваются из калькулятора, модели 6–10 можно посчитать упрощённо.
B12: 3. «Запуск»: разовые расходы на старт — товарный знак, сертификация, съёмка, сайт.
B13: 4. «Итог»: сколько денег нужно всего, средняя себестоимость, цена и сколько вещей продать, чтобы вернуть вложения.
B14: Золотистые ячейки — ваши данные. Остальное считается само.
B16: В А Ж Н О
... B25: Курс и бесплатная консультация: anna-zheltakova.com/course · Telegram: t.me/anyazheltakova

Sheet Итог
B1: М А Н У Ф А К Т У Р А 4 · К У Р С « Б Р Е Н Д П О Д К Л Ю Ч »
B2: СКОЛЬКО НУЖНО ДЕНЕГ
B3: Считается из листов «Калькулятор», «Капсула» и «Запуск». Золотистые ячейки можно менять.
B6: Пошив первой партии | C6: =Капсула!O16 -> 197055 | D6: Ткань, фурнитура, работа фабрики и оформление всех изделий
B7: Подготовка моделей (лекала, образцы, эталоны) | C7: =Капсула!N16 -> 94000 | D7: Инвестиции: возвращаются с будущих партий
B8: Разовые расходы на старт | C8: =Запуск!C18 -> 283000
B9: Резерв на непредвиденное, % | C9: 0.15 | D9: 10–15%: задержки, брак, недомер ткани
B10: Резерв, ₽ | C10: =(C6+C7+C8)*C9 -> 86108.25
B11: ВСЕГО НУЖНО НА ЗАПУСК | C11: =C6+C7+C8+C10 -> 660163.25 | D11: Столько денег нужно до первой продажи
B13: Изделий в первой партии, шт. | C13: =Капсула!E16 -> 45
B14: Средняя себестоимость единицы | C14: =IF(C13=0,0,C6/C13) -> 4379 | D14: Без учёта лекал и образцов
B15: Наценка (множитель к себестоимости) | C15: 3 | D15: Для розницы через свой сайт и соцсети часто ×2,5–3
B16: Средняя цена продажи | C16: =C14*C15 -> 13137 | D16: Цены по каналам — на листе «Калькулятор»
B17: Налог УСН «доходы», % | C17: 0.06 | D17: Откладывайте 6% с каждого поступления в отдельную «копилку»
B18: Возвраты и комиссии, % | C18: 0.1 | D18: Эквайринг, возвраты, доставка
B19: Прибыль с одной вещи | C19: =C16*(1-C17-C18)-C14 -> 6656.08 | D19: Без учёта рекламы и зарплат
B20: Выручка, если продать всю партию | C20: =C16*C13 -> 591165
B21: Сколько вещей продать, чтобы вернуть все вложения | C21: =IF(C19<=0,"цена ниже себестоимости",ROUNDUP(C11/C19,0)) -> 100 | D21: Если больше, чем в партии, — это нормально: вложения в старт окупаются за 2–4 партии
B24: Разобрать свою смету с Анной — бесплатная консультация: anna-zheltakova.com/course

Sheet Калькулятор
B1: М А Н У Ф А К Т У Р А 4 · К У Р С « Б Р Е Н Д П О Д К Л Ю Ч »
B2: КАЛЬКУЛЯТОР СЕБЕСТОИМОСТИ
B3: Пять моделей капсулы: себестоимость по статьям и цена для каждого канала продаж. Золотистые ячейки — ваши данные.
B5: СТАТЬЯ | C5: МОДЕЛЬ 1 | D5: МОДЕЛЬ 2 | E5: МОДЕЛЬ 3 | F5: МОДЕЛЬ 4 | G5: МОДЕЛЬ 5 | H5: ПОДСКАЗКА
B6: Название модели | C6: Платье-рубашка | D6: Жакет | E6: Брюки прямые | F6: Футболка | G6: Юбка миди | H6: Модели 1–5 сами попадут на лист «Капсула»
B8: Т К А Н И
B9: Основная ткань: расход, м на изделие | C9: 2.6 | D9: 1.9 | E9: 1.4 | F9: 0.9 | G9: 1.3 | H9: Возьмите из раскладки конструктора
B10: Основная ткань: цена, ₽ за метр | C10: 900 | D10: 1400 | E10: 1100 | F10: 600 | G10: 1000
B11: Подкладка: расход, м на изделие | C11: 0 | D11: 1.5 | E11: 0 | F11: 0 | G11: 0.9 | H11: 0, если подкладки нет
B12: Подкладка: цена, ₽ за метр | C12: 0 | D12: 350 | E12: 0 | F12: 0 | G12: 300
B13: Дублерин и клеевые материалы, ₽ | C13: 60 | D13: 180 | E13: 40 | F13: 0 | G13: 30 | H13: Жакеты, воротники, пояса
B14: Запас на раскладку и брак ткани, % | C14: 0.1 | D14: 0.1 | E14: 0.1 | F14: 0.1 | G14: 0.1 | H14: Обычно 8–12%: в рулоне бывает 27 м вместо 30
B15: Ткани на изделие | C15: =IF(C$6="","",(C9*C10+C11*C12)*(1+C14)+C13) -> 2634 | D15: =IF(D$6="","",(D9*D10+D11*D12)*(1+D14)+D13) -> 3683.5 | E15: =IF(E$6="","",(E9*E10+E11*E12)*(1+E14)+E13) -> 1734 | F15: =IF(F$6="","",(F9*F10+F11*F12)*(1+F14)+F13) -> 594 | G15: =IF(G$6="","",(G9*G10+G11*G12)*(1+G14)+G13) -> 1757
B17: Ф У Р Н И Т У Р А
B18: Пуговицы, кнопки, крючки, ₽ | C18: 120 | D18: 200 | E18: 30 | F18: 0 | G18: 0
B19: Молния, ₽ | C19: 0 | D19: 0 | E19: 60 | F19: 0 | G19: 60
B20: Нитки, тесьма, резинка, ₽ | C20: 40 | D20: 60 | E20: 40 | F20: 20 | G20: 30
B21: Прочая фурнитура, ₽ | C21: 0 | D21: 50 | E21: 0 | F21: 0 | G21: 0 | H21: Пряжки, люверсы, плечевые накладки
B22: Фурнитура на изделие | C22: =IF(C$6="","",C18+C19+C20+C21) -> 160 | D22: =IF(D$6="","",D18+D19+D20+D21) -> 310 | E22: =IF(E$6="","",E18+E19+E20+E21) -> 130 | F22: =IF(F$6="","",F18+F19+F20+F21) -> 20 | G22: =IF(G$6="","",G18+G19+G20+G21) -> 90
B24: Р А Б О Т А Ф А Б Р И К И
B25: Раскрой, ₽ | C25: 250 | D25: 350 | E25: 200 | F25: 80 | G25: 150 | H25: Часто входит в цену пошива — уточните у фабрики
B26: Пошив, ₽ | C26: 1500 | D26: 3200 | E26: 1200 | F26: 450 | G26: 1000 | H26: Жакет: 2 500–4 000 ₽. Дорогая швея шьёт 4 изделия за смену, а не 10
B27: ВТО (влажно-тепловая обработка), ₽ | C27: 150 | D27: 300 | E27: 150 | F27: 50 | G27: 100 | H27: Утюжка без ласов — то, за что платят в хорошем цехе
B28: ОТК (контроль качества), ₽ | C28: 50 | D28: 80 | E28: 50 | F28: 30 | G28: 40
B29: Работа на изделие | C29: =IF(C$6="","",C25+C26+C27+C28) -> 1950 | D29: =IF(D$6="","",D25+D26+D27+D28) -> 3930 | E29: =IF(E$6="","",E25+E26+E27+E28) -> 1600 | F29: =IF(F$6="","",F25+F26+F27+F28) -> 610 | G29: =IF(G$6="","",G25+G26+G27+G28) -> 1290
B31: О Ф О Р М Л Е Н И Е И Д О С Т А В К А
B32: Бирка, этикетка, составник, ₽ | C32: 40 | D32: 40 | E32: 40 | F32: 40 | G32: 40
B33: Код «Честного знака», ₽ | C33: 1 | D33: 1 | E33: 1 | F33: 1 | G33: 1 | H33: Около 0,60 ₽ + НДС за код
B34: Упаковка: пакет, вешалка, ₽ | C34: 60 | D34: 90 | E34: 60 | F34: 40 | G34: 60
B35: Доставка до склада, ₽ за изделие | C35: 50 | D35: 70 | E35: 50 | F35: 30 | G35: 50
B36: Оформление на изделие | C36: =IF(C$6="","",C32+C33+C34+C35) -> 151 | D36: =IF(D$6="","",D32+D33+D34+D35) -> 201 | E36: =IF(E$6="","",E32+E33+E34+E35) -> 151 | F36: =IF(F$6="","",F32+F33+F34+F35) -> 111 | G36: =IF(G$6="","",G32+G33+G34+G35) -> 151
B37: Резерв на брак пошива, % | C37: 0.03 | D37: 0.03 | E37: 0.03 | F37: 0.03 | G37: 0.03 | H37: 2–5%: часть партии уйдёт в уценку
B38: Себестоимость единицы | C38: =IF(C$6="","",ROUND((C15+C22+C29+C36)*(1+C37),0)) -> 5042 | D38: =IF(D$6="","",ROUND((D15+D22+D29+D36)*(1+D37),0)) -> 8368 | E38: =IF(E$6="","",ROUND((E15+E22+E29+E36)*(1+E37),0)) -> 3723 | F38: =IF(F$6="","",ROUND((F15+F22+F29+F36)*(1+F37),0)) -> 1375 | G38: =IF(G$6="","",ROUND((G15+G22+G29+G36)*(1+G37),0)) -> 3387 | H38: Без лекал и образцов: их считаем отдельно
B40: П О Д Г О Т О В К А М О Д Е Л И ( И Н В Е С Т И Ц И И )
B41: Лекала и градация, ₽ | C41: 12000 | D41: 18000 | E41: 10000 | F41: 6000 | G41: 8000 | H41: Платится один раз на модель
B42: Образец и эталон, ₽ | C42: 9000 | D42: 14000 | E42: 7000 | F42: 4000 | G42: 6000
B43: Изделий в первой партии, шт. | C43: =Капсула!E6 -> 9 | D43: =Капсула!E7 -> 9 | E43: =Капсула!E8 -> 9 | F43: =Капсула!E9 -> 9 | G43: =Капсула!E10 -> 9 | H43: Из листа «Капсула»: размеров × шт. на размер
B44: Подготовка на 1 изделие первой партии | C44: =IF(C$6="","",IF(N(C43)=0,0,ROUND((C41+C42)/C43,0))) -> 2333 | D44: =IF(D$6="","",IF(N(D43)=0,0,ROUND((D41+D42)/D43,0))) -> 3556 | E44: =IF(E$6="","",IF(N(E43)=0,0,ROUND((E41+E42)/E43,0))) -> 1889 | F44: =IF(F$6="","",IF(N(F43)=0,0,ROUND((F41+F42)/F43,0))) -> 1111 | G44: =IF(G$6="","",IF(N(G43)=0,0,ROUND((G41+G42)/G43,0))) -> 1556 | H44: Столько стоила бы вещь, если вернуть подготовку с первой партии
B45: Себестоимость с подготовкой | C45: =IF(C$6="","",C38+C44) -> 7375 | D45: =IF(D$6="","",D38+D44) -> 11924 | E45: =IF(E$6="","",E38+E44) -> 5612 | F45: =IF(F$6="","",F38+F44) -> 2486 | G45: =IF(G$6="","",G38+G44) -> 4943 | H45: Не ставьте цену от этой суммы: подготовка окупается за 2–4 партии
B47: Ц Е Н А И П Р И Б Ы Л Ь П О К А Н А Л А М П Р О Д А Ж
...

Sheet Капсула
B1: М А Н У Ф А К Т У Р А 4 · К У Р С « Б Р Е Н Д П О Д К Л Ю Ч »
B2: ПЕРВАЯ КАПСУЛА
B3: Модели 1–5 считаются в «Калькуляторе». Здесь — сколько штук шьёте. Модели 6–10 можно посчитать упрощённо.
B5: МОДЕЛЬ | C5: РАЗМЕРОВ | D5: ШТ. НА РАЗМЕР | E5: ВСЕГО ШТ. | F5: РАСХОД ТКАНИ, М/ШТ. | G5: ЦЕНА ТКАНИ, ₽/М | H5: ФУРНИТУРА, ₽/ШТ. | I5: РАБОТА ФАБРИКИ, ₽/ШТ. | J5: ОФОРМЛЕНИЕ И ДОСТАВКА, ₽/ШТ. | K5: СЕБЕСТОИМОСТЬ ЕД., ₽ | L5: ЛЕКАЛА + ГРАДАЦИЯ, ₽ | M5: ОБРАЗЕЦ + ЭТАЛОН, ₽ | N5: ПОДГОТОВКА МОДЕЛИ, ₽ | O5: ПАРТИЯ, ₽
B6: =IF(Калькулятор!C6="","",Калькулятор!C6) -> Платье-рубашка | C6: 3 | D6: 3 | E6: =IF(B6="","",C6*D6) -> 9 | F6: =IF(Калькулятор!C$6="","",Калькулятор!C9) -> 2.6 | G6: =IF(Калькулятор!C$6="","",Калькулятор!C10) -> 900 | H6: =IF(Калькулятор!C$6="","",Калькулятор!C22) -> 160 | I6: =IF(Калькулятор!C$6="","",Калькулятор!C29) -> 1950 | J6: =IF(Калькулятор!C$6="","",Калькулятор!C36) -> 151 | K6: =IF(Калькулятор!C$6="","",Калькулятор!C38) -> 5042 | L6: =IF(Калькулятор!C$6="","",Калькулятор!C41) -> 12000 | M6: =IF(Калькулятор!C$6="","",Калькулятор!C42) -> 9000 | N6: =IF(B6="","",L6+M6) -> 21000 | O6: =IF(B6="","",K6*E6) -> 45378
B7: =IF(Калькулятор!D6="","",Калькулятор!D6) -> Жакет | C7: 3 | D7: 3 | E7: =IF(B7="","",C7*D7) -> 9 | F7: =IF(Калькулятор!D$6="","",Калькулятор!D9) -> 1.9 | G7: =IF(Калькулятор!D$6="","",Калькулятор!D10) -> 1400 | H7: =IF(Калькулятор!D$6="","",Калькулятор!D22) -> 310 | I7: =IF(Калькулятор!D$6="","",Калькулятор!D29) -> 3930 | J7: =IF(Калькулятор!D$6="","",Калькулятор!D36) -> 201 | K7: =IF(Калькулятор!D$6="","",Калькулятор!D38) -> 8368 | L7: =IF(Калькулятор!D$6="","",Калькулятор!D41) -> 18000 | M7: =IF(Калькулятор!D$6="","",Калькулятор!D42) -> 14000 | N7: =IF(B7="","",L7+M7) -> 32000 | O7: =IF(B7="","",K7*E7) -> 75312
B8: =IF(Калькулятор!E6="","",Калькулятор!E6) -> Брюки прямые | C8: 3 | D8: 3 | E8: =IF(B8="","",C8*D8) -> 9 | F8: =IF(Калькулятор!E$6="","",Калькулятор!E9) -> 1.4 | G8: =IF(Калькулятор!E$6="","",Калькулятор!E10) -> 1100 | H8: =IF(Калькулятор!E$6="","",Калькулятор!E22) -> 130 | I8: =IF(Калькулятор!E$6="","",Калькулятор!E29) -> 1600 | J8: =IF(Калькулятор!E$6="","",Калькулятор!E36) -> 151 | K8: =IF(Калькулятор!E$6="","",Калькулятор!E38) -> 3723 | L8: =IF(Калькулятор!E$6="","",Калькулятор!E41) -> 10000 | M8: =IF(Калькулятор!E$6="","",Калькулятор!E42) -> 7000 | N8: =IF(B8="","",L8+M8) -> 17000 | O8: =IF(B8="","",K8*E8) -> 33507
B9: =IF(Калькулятор!F6="","",Калькулятор!F6) -> Футболка | C9: 3 | D9: 3 | E9: =IF(B9="","",C9*D9) -> 9 | F9: =IF(Калькулятор!F$6="","",Калькулятор!F9) -> 0.9 | G9: =IF(Калькулятор!F$6="","",Калькулятор!F10) -> 600 | H9: =IF(Калькулятор!F$6="","",Калькулятор!F22) -> 20 | I9: =IF(Калькулятор!F$6="","",Калькулятор!F29) -> 610 | J9: =IF(Калькулятор!F$6="","",Калькулятор!F36) -> 111 | K9: =IF(Калькулятор!F$6="","",Калькулятор!F38) -> 1375 | L9: =IF(Калькулятор!F$6="","",Калькулятор!F41) -> 6000 | M9: =IF(Калькулятор!F$6="","",Калькулятор!F42) -> 4000 | N9: =IF(B9="","",L9+M9) -> 10000 | O9: =IF(B9="","",K9*E9) -> 12375
B10: =IF(Калькулятор!G6="","",Калькулятор!G6) -> Юбка миди | C10: 3 | D10: 3 | E10: =IF(B10="","",C10*D10) -> 9 | F10: =IF(Калькулятор!G$6="","",Калькулятор!G9) -> 1.3 | G10: =IF(Калькулятор!G$6="","",Калькулятор!G10) -> 1000 | H10: =IF(Калькулятор!G$6="","",Калькулятор!G22) -> 90 | I10: =IF(Калькулятор!G$6="","",Калькулятор!G29) -> 1290 | J10: =IF(Калькулятор!G$6="","",Калькулятор!G36) -> 151 | K10: =IF(Калькулятор!G$6="","",Калькулятор!G38) -> 3387 | L10: =IF(Калькулятор!G$6="","",Калькулятор!G41) -> 8000 | M10: =IF(Калькулятор!G$6="","",Калькулятор!G42) -> 6000 | N10: =IF(B10="","",L10+M10) -> 14000 | O10: =IF(B10="","",K10*E10) -> 30483
E11: =IF(B11="","",C11*D11) | K11: =IF(B11="","",F11*G11*1.1+H11+I11+J11) | N11: =IF(B11="","",L11+M11) | O11: =IF(B11="","",K11*E11)
E12: =IF(B12="","",C12*D12) | K12: =IF(B12="","",F12*G12*1.1+H12+I12+J12) | N12: =IF(B12="","",L12+M12) | O12: =IF(B12="","",K12*E12)
E13: =IF(B13="","",C13*D13) | K13: =IF(B13="","",F13*G13*1.1+H13+I13+J13) | N13: =IF(B13="","",L13+M13) | O13: =IF(B13="","",K13*E13)
E14: =IF(B14="","",C14*D14) | K14: =IF(B14="","",F14*G14*1.1+H14+I14+J14) | N14: =IF(B14="","",L14+M14) | O14: =IF(B14="","",K14*E14)
E15: =IF(B15="","",C15*D15) | K15: =IF(B15="","",F15*G15*1.1+H15+I15+J15) | N15: =IF(B15="","",L15+M15) | O15: =IF(B15="","",K15*E15)
B16: ИТОГО | E16: =SUM(E6:E15) -> 45 | N16: =SUM(N6:N15) -> 94000 | O16: =SUM(O6:O15) -> 197055
B18: Модели 1–5: себестоимость из «Калькулятора» (ткань с подкладкой, фурнитура, раскрой, пошив, ВТО, ОТК, оформление, резерв на брак). Модели 6–10: расход × цена ткани × 1,1 + фурнитура + работа + оформление. Лекала и образцы — инвестиции: не вкладывайте их в цену первой партии.

Sheet Запуск
B1: М А Н У Ф А К Т У Р А 4 · К У Р С « Б Р Е Н Д П О Д К Л Ю Ч »
B2: РАЗОВЫЕ РАСХОДЫ НА СТАРТ
B3: Ориентиры для начинающего бренда. Уточните у подрядчиков в своём городе.
B5: СТАТЬЯ | C5: СУММА, ₽ | D5: КОММЕНТАРИЙ
B6: Мудборд, журналы, пробковая доска | C6: 3000 | D6: Домашнее задание урока 1: начните с насмотренности
B7: Регистрация товарного знака | C7: 45000 | D7: Пошлины Роспатента + проверка названия. Сначала проверьте, что имя свободно
B8: Сертификация / декларация соответствия | C8: 20000 | D8: Зависит от группы изделий; список сертифицирующих компаний есть в курсе
B9: Маркировка «Честный знак»: регистрация, принтер этикеток | C9: 15000 | D9: Обязательна для большинства групп одежды
B10: Имиджевая съёмка капсулы | C10: 50000 | D10: Начинающему бренду — до 50 тыс. ₽, профессиональная — до 150 тыс. ₽
B11: Предметная съёмка на белом фоне | C11: 15000 | D11: Для сайта и маркетплейсов
B12: Сайт с корзиной (Tilda) | C12: 50000 | D12: Шаблон дешевле, но сайт с оплатой повышает доверие
B13: Онлайн-касса и эквайринг | C13: 10000
B14: Бирки, этикетки, упаковка (тираж) | C14: 15000
B15: Реклама на запуск | C15: 50000 | D15: Первые продажи и тест аудитории
B16: Логистика: доставка ткани, образцов, партии | C16: 10000
B17: Другое | C17: 0
B18: ИТОГО | C18: =SUM(C6:C17) -> 283000
